Traceback (most recent call last):
  File "/home/alvaro/anaconda3/envs/pymc_env/lib/python3.11/site-packages/jupyter_cache/executors/utils.py", line 58, in single_nb_execution
    executenb(
  File "/home/alvaro/anaconda3/envs/pymc_env/lib/python3.11/site-packages/nbclient/client.py", line 1305, in execute
    return NotebookClient(nb=nb, resources=resources, km=km, **kwargs).execute()
           ^^^^^^^^^^^^^^^^^^^^^^^^^^^^^^^^^^^^^^^^^^^^^^^^^^^^^^^^^^^^^^^^^^^^^
  File "/home/alvaro/anaconda3/envs/pymc_env/lib/python3.11/site-packages/jupyter_core/utils/__init__.py", line 166, in wrapped
    return loop.run_until_complete(inner)
           ^^^^^^^^^^^^^^^^^^^^^^^^^^^^^^
  File "/home/alvaro/anaconda3/envs/pymc_env/lib/python3.11/asyncio/base_events.py", line 653, in run_until_complete
    return future.result()
           ^^^^^^^^^^^^^^^
  File "/home/alvaro/anaconda3/envs/pymc_env/lib/python3.11/site-packages/nbclient/client.py", line 705, in async_execute
    await self.async_execute_cell(
  File "/home/alvaro/anaconda3/envs/pymc_env/lib/python3.11/site-packages/nbclient/client.py", line 1058, in async_execute_cell
    await self._check_raise_for_error(cell, cell_index, exec_reply)
  File "/home/alvaro/anaconda3/envs/pymc_env/lib/python3.11/site-packages/nbclient/client.py", line 914, in _check_raise_for_error
    raise CellExecutionError.from_cell_and_msg(cell, exec_reply_content)
nbclient.exceptions.CellExecutionError: An error occurred while executing the following cell:
------------------
import imageio.v2 as imageio
import numpy as np
import matplotlib.pyplot as plt

# carregar e exibir imagens da "base de dados"
img1 = imageio.imread("dados/cebolinha3.jpg")
img2 = imageio.imread("dados/cebolinha2.jpg")

# carregar imagem de consulta e codificar funcao de distancia
# computar as distancias e exibir
imgQ = imageio.imread("dados/cebolinha1.jpg")

def Euclidean_distance(A, B):
    """ Calcula a distancia Euclidiana entre dois vetores de mesmo tamanho"""
    return  np.sqrt( np.sum((A-B)**2) )

dQ1 = Euclidean_distance(imgQ, img1)
dQ2 = Euclidean_distance(imgQ, img2)

plt.figure(figsize=(9,3))
plt.subplot(131); plt.imshow(imgQ); plt.title('Consulta')
plt.subplot(132); plt.imshow(img1); plt.title('Rank 1 : %.1f' % dQ1)
plt.subplot(133); plt.imshow(img2); plt.title('Rank 2 : %.1f' % dQ2)
------------------


[0;31m---------------------------------------------------------------------------[0m
[0;31mModuleNotFoundError[0m                       Traceback (most recent call last)
Cell [0;32mIn[1], line 1[0m
[0;32m----> 1[0m [38;5;28;01mimport[39;00m [38;5;21;01mimageio[39;00m[38;5;21;01m.[39;00m[38;5;21;01mv2[39;00m [38;5;28;01mas[39;00m [38;5;21;01mimageio[39;00m
[1;32m      2[0m [38;5;28;01mimport[39;00m [38;5;21;01mnumpy[39;00m [38;5;28;01mas[39;00m [38;5;21;01mnp[39;00m
[1;32m      3[0m [38;5;28;01mimport[39;00m [38;5;21;01mmatplotlib[39;00m[38;5;21;01m.[39;00m[38;5;21;01mpyplot[39;00m [38;5;28;01mas[39;00m [38;5;21;01mplt[39;00m

[0;31mModuleNotFoundError[0m: No module named 'imageio'

