Traceback (most recent call last):
  File "/home/alvaro/anaconda3/envs/pymc_env/lib/python3.11/site-packages/jupyter_cache/executors/utils.py", line 58, in single_nb_execution
    executenb(
  File "/home/alvaro/anaconda3/envs/pymc_env/lib/python3.11/site-packages/nbclient/client.py", line 1305, in execute
    return NotebookClient(nb=nb, resources=resources, km=km, **kwargs).execute()
           ^^^^^^^^^^^^^^^^^^^^^^^^^^^^^^^^^^^^^^^^^^^^^^^^^^^^^^^^^^^^^^^^^^^^^
  File "/home/alvaro/anaconda3/envs/pymc_env/lib/python3.11/site-packages/jupyter_core/utils/__init__.py", line 166, in wrapped
    return loop.run_until_complete(inner)
           ^^^^^^^^^^^^^^^^^^^^^^^^^^^^^^
  File "/home/alvaro/anaconda3/envs/pymc_env/lib/python3.11/asyncio/base_events.py", line 653, in run_until_complete
    return future.result()
           ^^^^^^^^^^^^^^^
  File "/home/alvaro/anaconda3/envs/pymc_env/lib/python3.11/site-packages/nbclient/client.py", line 705, in async_execute
    await self.async_execute_cell(
  File "/home/alvaro/anaconda3/envs/pymc_env/lib/python3.11/site-packages/nbclient/client.py", line 1058, in async_execute_cell
    await self._check_raise_for_error(cell, cell_index, exec_reply)
  File "/home/alvaro/anaconda3/envs/pymc_env/lib/python3.11/site-packages/nbclient/client.py", line 914, in _check_raise_for_error
    raise CellExecutionError.from_cell_and_msg(cell, exec_reply_content)
nbclient.exceptions.CellExecutionError: An error occurred while executing the following cell:
------------------
from pdf2image import convert_from_path
from PIL import Image

# Converte o PDF em imagens
images = convert_from_path('nfe-avaliacao.pdf')

# Salva a primeira pÃ¡gina do PDF como PNG
images[0].save('nfe-avaliacao.png', 'PNG')

# Carrega a imagem PNG
img = Image.open('nfe-avaliacao.png')

# ObtÃ©m a resoluÃ§Ã£o da imagem
resolution = img.size

print(f'A resoluÃ§Ã£o da imagem Ã©: {resolution}')
------------------


[0;31m---------------------------------------------------------------------------[0m
[0;31mModuleNotFoundError[0m                       Traceback (most recent call last)
Cell [0;32mIn[1], line 1[0m
[0;32m----> 1[0m [38;5;28;01mfrom[39;00m [38;5;21;01mpdf2image[39;00m [38;5;28;01mimport[39;00m convert_from_path
[1;32m      2[0m [38;5;28;01mfrom[39;00m [38;5;21;01mPIL[39;00m [38;5;28;01mimport[39;00m Image
[1;32m      4[0m [38;5;66;03m# Converte o PDF em imagens[39;00m

[0;31mModuleNotFoundError[0m: No module named 'pdf2image'

